Workbook

Sheet Data
A1: Visitor_ID | B1: Page_Views | C1: Session_Duration | D1: Bounce_Rate | E1: Conversion_Rate | F1: Traffic_Source | G1: Exit_Pages | H1: Load_Time | I1: Visitor_Type | J1: Location
A2: 1 | B2: 5 | C2: 711.33 | D2: 0.57 | E2: 0.05 | F2: Organic | G2: Contact Us | H2: 1.31 | I2: New | J2: Chicago
A3: 2 | B3: 4 | C3: 221.4 | D3: 0.1 | E3: 0.05 | F3: Social Media | G3: Checkout | H3: 2.01 | I3: Returning | J3: Charlotte
A4: 3 | B4: 4 | C4: 704.4 | D4: 0.8 | E4: 0.03 | F4: Organic | G4: Homepage | H4: 2.38 | I4: Returning | J4: Charlotte | L4: Total no. of visitors | M4: 5869
A5: 4 | B5: 5 | C5: 695.65 | D5: 0.26 | E5: 0.06 | F5: Direct | G5: Blog | H5: 2.21 | I5: New | J5: Austin
A6: 5 | B6: 5 | C6: 65.83 | D6: 0.55 | E6: 0.03 | F6: Referral | G6: Product Page | H6: 2.22 | I6: New | J6: San Jose | L6: DATA | M6: AVG | N6: MAX | O6: MIN
A7: 6 | B7: 3 | C7: 143.69 | D7: 0.51 | E7: 0.04 | F7: Social Media | G7: Blog | H7: 1.93 | I7: New | J7: Washington | L7: Page Views | M7: =AVERAGE(B2:B5870) -> 5.0126086 | N7: =MAX(B2:B5870) -> 15 | O7: =MIN(B2:B5870) -> 0
A8: 7 | B8: 5 | C8: 43.38 | D8: 0.24 | E8: 0.01 | F8: Referral | G8: Product Page | H8: 1.21 | I8: New | J8: Charlotte | L8: Session Duration | M8: =AVERAGE(C2:C5870) -> 299.99049 | N8: =MAX(C2:C5870) -> 2166.2 | O8: =MIN(C2:C5870) -> 0.05
A9: 8 | B9: 4 | C9: 447.47 | D9: 0.12 | E9: 0.06 | F9: Social Media | G9: Homepage | H9: 1.08 | I9: Returning | J9: Philadelphia | L9: Load Time | M9: =AVERAGE(H2:H5870) -> 2.0050417 | N9: =MAX(H2:H5870) -> 3.89 | O9: =MIN(H2:H5870) -> 0.24
A10: 9 | B10: 6 | C10: 210.43 | D10: 0.21 | E10: 0.07 | F10: Referral | G10: Homepage | H10: 2.14 | I10: Returning | J10: Los Angeles | L10: BR | M10: =AVERAGE(D2:D5870) -> 0.49724655 | N10: =MAX(D2:D5870) -> 1 | O10: =MIN(D2:D5870) -> 0
A11: 10 | B11: 7 | C11: 792.71 | D11: 0.1 | E11: 0.08 | F11: Referral | G11: Contact Us | H11: 2.1 | I11: New | J11: Jacksonville | L11: CR | M11: =AVERAGE(E2:E5870) -> 0.050069859 | N11: =MAX(E2:E5870) -> 0.1 | O11: =MIN(E2:E5870) -> 0
A12: 11 | B12: 2 | C12: 70.04 | D12: 0.28 | E12: 0.09 | F12: Referral | G12: Product Page | H12: 2.49 | I12: New | J12: Houston
A13: 12 | B13: 5 | C13: 349.78 | D13: 1 | E13: 0.08 | F13: Direct | G13: Checkout | H13: 1.3 | I13: Returning | J13: Indianapolis
A14: 13 | B14: 5 | C14: 1359.49 | D14: 0.4 | E14: 0.02 | F14: Organic | G14: Blog | H14: 1.36 | I14: Returning | J14: San Jose
A15: 14 | B15: 6 | C15: 328.43 | D15: 0.86 | E15: 0.02 | F15: Social Media | G15: Checkout | H15: 2.1 | I15: Returning | J15: Denver
A16: 15 | B16: 4 | C16: 21.38 | D16: 0.55 | E16: 0.09 | F16: Direct | G16: Product Page | H16: 1.68 | I16: New | J16: Indianapolis
A17: 16 | B17: 6 | C17: 266.33 | D17: 0.67 | E17: 0.08 | F17: Direct | G17: Checkout | H17: 1.84 | I17: New | J17: Los Angeles
A18: 17 | B18: 6 | C18: 59.48 | D18: 0.16 | E18: 0.08 | F18: Referral | G18: Product Page | H18: 1.33 | I18: Returning | J18: Denver
A19: 18 | B19: 1 | C19: 9.29 | D19: 0.27 | E19: 0.07 | F19: Social Media | G19: Contact Us | H19: 2.18 | I19: New | J19: San Antonio
A20: 19 | B20: 7 | C20: 122.37 | D20: 0.51 | E20: 0.03 | F20: Social Media | G20: Contact Us | H20: 1.89 | I20: New | J20: Indianapolis
A21: 20 | B21: 2 | C21: 92.82 | D21: 0.88 | E21: 0.08 | F21: Social Media | G21: Checkout | H21: 2.15 | I21: New | J21: Austin
A22: 21 | B22: 11 | C22: 466.44 | D22: 0.04 | E22: 0.01 | F22: Social Media | G22: Checkout | H22: 2.43 | I22: New | J22: Phoenix
A23: 22 | B23: 4 | C23: 140.37 | D23: 0.51 | E23: 0.04 | F23: Social Media | G23: Product Page | H23: 1.37 | I23: New | J23: Columbus
... A5870: 5870 | B5870: 4 | C5870: 757.45 | D5870: 0.36 | E5870: 0.07 | F5870: Organic | G5870: Product Page | H5870: 1.21 | I5870: New | J5870: San Antonio

Sheet Visitor Type
A1: Visitor_Type | B1: =Data!G1 -> Exit_Pages | C1: =Data!F1 -> Traffic_Source | J1: Row Labels | K1: Count of Visitor_Type
A2: Returning | B2: =Data!G2 -> Contact Us | C2: =Data!F2 -> Organic | E2: {=_xlfn.UNIQUE(A1:A5870,FALSE)} -> Visitor_Type | G2: Percentage | J2: Blog | K2: 455
A3: New | B3: =Data!G3 -> Checkout | C3: =Data!F3 -> Social Media | E3: Returning | F3: =COUNTIF(A2:A5870,E3) -> 2350 | G3: =F3/F5 -> 0.40040893 | J3: Checkout | K3: 496
A4: Returning | B4: =Data!G4 -> Homepage | C4: =Data!F4 -> Organic | E4: New | F4: =COUNTIF(A2:A5870,E4) -> 3519 | G4: =F4/F5 -> 0.59959107 | J4: Contact Us | K4: 484
A5: Returning | B5: =Data!G5 -> Blog | C5: =Data!F5 -> Direct | E5: Total | F5: 5869 | J5: Homepage | K5: 453
A6: Returning | B6: =Data!G6 -> Product Page | C6: =Data!F6 -> Referral | J6: Product Page | K6: 462
A7: Returning | B7: =Data!G7 -> Blog | C7: =Data!F7 -> Social Media | J7: Grand Total | K7: 2350
A8: New | B8: =Data!G8 -> Product Page | C8: =Data!F8 -> Referral
A9: New | B9: =Data!G9 -> Homepage | C9: =Data!F9 -> Social Media | E9: {=_xlfn.UNIQUE(B1:B5870,FALSE)} -> Exit_Pages | G9: Percentage
A10: New | B10: =Data!G10 -> Homepage | C10: =Data!F10 -> Referral | E10: Contact Us | F10: =COUNTIF(B2:B5870,E10) -> 1177 | G10: =F10/$F$15 -> 0.20054524
A11: New | B11: =Data!G11 -> Contact Us | C11: =Data!F11 -> Referral | E11: Checkout | F11: =COUNTIF($B$2:$B$5870,E11) -> 1162 | G11: =F11/$F$15 -> 0.19798944
A12: Returning | B12: =Data!G12 -> Product Page | C12: =Data!F12 -> Referral | E12: Homepage | F12: =COUNTIF($B$2:$B$5870,E12) -> 1149 | G12: =F12/$F$15 -> 0.19577441
A13: Returning | B13: =Data!G13 -> Checkout | C13: =Data!F13 -> Direct | E13: Blog | F13: =COUNTIF($B$2:$B$5870,E13) -> 1174 | G13: =F13/$F$15 -> 0.20003408
A14: New | B14: =Data!G14 -> Blog | C14: =Data!F14 -> Organic | E14: Product Page | F14: =COUNTIF($B$2:$B$5870,E14) -> 1207 | G14: =F14/$F$15 -> 0.20565684
A15: Returning | B15: =Data!G15 -> Checkout | C15: =Data!F15 -> Social Media | E15: Total | F15: =SUM(F10:F14) -> 5869
A16: New | B16: =Data!G16 -> Product Page | C16: =Data!F16 -> Direct
A17: New | B17: =Data!G17 -> Checkout | C17: =Data!F17 -> Direct
A18: New | B18: =Data!G18 -> Product Page | C18: =Data!F18 -> Referral
A19: Returning | B19: =Data!G19 -> Contact Us | C19: =Data!F19 -> Social Media | E19: {=_xlfn.UNIQUE(C1:C5870,FALSE)} -> Traffic_Source | G19: Percentage | J19: Row Labels | K19: Count of Visitor_Type
A20: New | B20: =Data!G20 -> Contact Us | C20: =Data!F20 -> Social Media | E20: Organic | F20: =COUNTIF($C$2:$C$5870,E20) -> 1450 | G20: =F20/$F$24 -> 0.24706083 | J20: Direct | K20: 595
A21: New | B21: =Data!G21 -> Checkout | C21: =Data!F21 -> Social Media | E21: Social Media | F21: =COUNTIF($C$2:$C$5870,E21) -> 1515 | G21: =F21/$F$24 -> 0.25813597 | J21: Organic | K21: 561
A22: Returning | B22: =Data!G22 -> Checkout | C22: =Data!F22 -> Social Media | E22: Direct | F22: =COUNTIF($C$2:$C$5870,E22) -> 1488 | G22: =F22/$F$24 -> 0.25353553 | J22: Referral | K22: 561
A23: Returning | B23: =Data!G23 -> Product Page | C23: =Data!F23 -> Social Media | E23: Referral | F23: =COUNTIF($C$2:$C$5870,E23) -> 1416 | G23: =F23/$F$24 -> 0.24126768 | J23: Social Media | K23: 633
A24: New | B24: =Data!G24 -> Contact Us | C24: =Data!F24 -> Direct | E24: Total | F24: =SUM(F20:F23) -> 5869 | J24: Grand Total | K24: 2350
A25: New | B25: =Data!G25 -> Checkout | C25: =Data!F25 -> Social Media
A26: New | B26: =Data!G26 -> Product Page | C26: =Data!F26 -> Direct
A27: New | B27: =Data!G27 -> Product Page | C27: =Data!F27 -> Social Media
A28: New | B28: =Data!G28 -> Checkout | C28: =Data!F28 -> Referral
A29: Returning | B29: =Data!G29 -> Blog | C29: =Data!F29 -> Direct
A30: Returning | B30: =Data!G30 -> Homepage | C30: =Data!F30 -> Direct
A31: New | B31: =Data!G31 -> Product Page | C31: =Data!F31 -> Social Media
A32: Returning | B32: =Data!G32 -> Contact Us | C32: =Data!F32 -> Social Media
A33: New | B33: =Data!G33 -> Homepage | C33: =Data!F33 -> Organic
A34: New | B34: =Data!G34 -> Product Page | C34: =Data!F34 -> Referral
A35: Returning | B35: =Data!G35 -> Blog | C35: =Data!F35 -> Referral
A36: New | B36: =Data!G36 -> Homepage | C36: =Data!F36 -> Direct
... A5870: Returning | B5870: =Data!G5870 -> Product Page | C5870: =Data!F5870 -> Organic

Sheet Load Time
A1: Load_Time | C1: Load Time below avg | D1: load time above avg
A2: 2 | C2: 2 | D2: 2.59 | F2: t-Test: Two-Sample Assuming Equal Variances | G2: Significant difference
A3: 1.51 | C3: 1.51 | D3: 2.38
A4: 1.72 | C4: 1.72 | D4: 2.65 | G4: Load Time below avg | H4: load time above avg
A5: 1.96 | C5: 1.96 | D5: 2.19 | F5: Mean | G5: 1.6121474 | H5: 2.4040076
A6: 1.47 | C6: 1.47 | D6: 2.21 | F6: Variance | G6: 0.087253269 | H6: 0.091382251
A7: 1.83 | C7: 1.83 | D7: 2.54 | F7: Observations | G7: 2957 | H7: 2912
A8: 1.91 | C8: 1.91 | D8: 2.22 | F8: Pooled Variance | G8: 0.089301925
A9: 1.61 | C9: 1.61 | D9: 2.27 | F9: Hypothesized Mean Difference | G9: 0
A10: 1.54 | C10: 1.54 | D10: 2.07 | F10: df | G10: 5867
A11: 1.01 | C11: 1.01 | D11: 2.21 | F11: t Stat | G11: -101.49797
A12: 1.6 | C12: 1.6 | D12: 2.8 | F12: P(T<=t) one-tail | G12: 0
A13: 1.83 | C13: 1.83 | D13: 2.12 | F13: t Critical one-tail | G13: 1.6451134
A14: 1.54 | C14: 1.54 | D14: 2.2 | F14: P(T<=t) two-tail | G14: 0
A15: 1.72 | C15: 1.72 | D15: 2.57 | F15: t Critical two-tail | G15: 1.9603684
A16: 1.88 | C16: 1.88 | D16: 2.55
A17: 1.83 | C17: 1.83 | D17: 2.47
A18: 1.28 | C18: 1.28 | D18: 3.14
A19: 1.57 | C19: 1.57 | D19: 2.25
A20: 1.54 | C20: 1.54 | D20: 2.44
A21: 1.95 | C21: 1.95 | D21: 2.43
A22: 1.79 | C22: 1.79 | D22: 2.42
A23: 1.96 | C23: 1.96 | D23: 2.36
A24: 1.54 | C24: 1.54 | D24: 2.3
A25: 1.8 | C25: 1.8 | D25: 2.03
A26: 1.48 | C26: 1.48 | D26: 2.12
A27: 1.38 | C27: 1.38 | D27: 2.07
... A2913: 1.69 | C2913: 1.69 | D2913: 2.08
A2914: 1.72 | C2914: 1.72
A2915: 1.78 | C2915: 1.78
A2916: 1.22 | C2916: 1.22
A2917: 1.67 | C2917: 1.67
A2918: 1.94 | C2918: 1.94
A2919: 1.05 | C2919: 1.05
A2920: 1.32 | C2920: 1.32
A2921: 1.87 | C2921: 1.87
A2922: 1.21 | C2922: 1.21
A2923: 1.93 | C2923: 1.93
A2924: 1.57 | C2924: 1.57
A2925: 1.96 | C2925: 1.96
...

Sheet RA
A1: Load_Time | B1: =Data!D1 -> Bounce_Rate | C1: =Data!E1 -> Conversion_Rate
A2: 2.59 | B2: =Data!D2 -> 0.57 | C2: =Data!E2 -> 0.05 | E2: SUMMARY OUTPUT | F2: No significant impact of load time on Bounce Rate | P2: SUMMARY OUTPUT | Q2: No significant impact of load time on Conversion Rate
A3: 2.38 | B3: =Data!D3 -> 0.1 | C3: =Data!E3 -> 0.05
A4: 2.65 | B4: =Data!D4 -> 0.8 | C4: =Data!E4 -> 0.03 | E4: Regression Statistics | P4: Regression Statistics
A5: 2 | B5: =Data!D5 -> 0.26 | C5: =Data!E5 -> 0.06 | E5: Multiple R | F5: 0.0010109692 | P5: Multiple R | Q5: 0.012109476
A6: 2.19 | B6: =Data!D6 -> 0.55 | C6: =Data!E6 -> 0.03 | E6: R Square | F6: 1.0220588e-06 | P6: R Square | Q6: 0.00014663941
A7: 1.51 | B7: =Data!D7 -> 0.51 | C7: =Data!E7 -> 0.04 | E7: Adjusted R Square | F7: -0.00016942263 | P7: Adjusted R Square | Q7: -2.3780461e-05
A8: 2.21 | B8: =Data!D8 -> 0.24 | C8: =Data!E8 -> 0.01 | E8: Standard Error | F8: 0.2891848 | P8: Standard Error | Q8: 0.029135434
A9: 1.72 | B9: =Data!D9 -> 0.12 | C9: =Data!E9 -> 0.06 | E9: Observations | F9: 5869 | P9: Observations | Q9: 5869
A10: 2.54 | B10: =Data!D10 -> 0.21 | C10: =Data!E10 -> 0.07
A11: 2.22 | B11: =Data!D11 -> 0.1 | C11: =Data!E11 -> 0.08 | E11: ANOVA | P11: ANOVA
A12: 2.27 | B12: =Data!D12 -> 0.28 | C12: =Data!E12 -> 0.09 | F12: df | G12: SS | H12: MS | I12: F | J12: Significance F | Q12: df | R12: SS | S12: MS | T12: F | U12: Significance F
A13: 2.07 | B13: =Data!D13 -> 1 | C13: =Data!E13 -> 0.08 | E13: Regression | F13: 1 | G13: 0.00050146816 | H13: 0.00050146816 | I13: 0.0059964252 | J13: 0.93827888 | P13: Regression | Q13: 1 | R13: 0.00073042135 | S13: 0.00073042135 | T13: 0.86045957 | U13: 0.35364827
A14: 2.21 | B14: =Data!D14 -> 0.4 | C14: =Data!E14 -> 0.02 | E14: Residual | F14: 5867 | G14: 490.6446 | H14: 0.083627851 | P14: Residual | Q14: 5867 | R14: 4.9803409 | S14: 0.00084887352
A15: 1.96 | B15: =Data!D15 -> 0.86 | C15: =Data!E15 -> 0.02 | E15: Total | F15: 5868 | G15: 490.6451 | P15: Total | Q15: 5868 | R15: 4.9810714
A16: 2.8 | B16: =Data!D16 -> 0.55 | C16: =Data!E16 -> 0.09
A17: 2.12 | B17: =Data!D17 -> 0.67 | C17: =Data!E17 -> 0.08 | F17: Coefficients | G17: Standard Error | H17: t Stat | I17: P-value | J17: Lower 95% | K17: Upper 95% | L17: Lower 95.0% | M17: Upper 95.0% | Q17: Coefficients | R17: Standard Error | S17: t Stat | T17: P-value | U17: Lower 95% | V17: Upper 95% | W17: Lower 95.0% | X17: Upper 95.0%
A18: 2.2 | B18: =Data!D18 -> 0.16 | C18: =Data!E18 -> 0.08 | E18: Intercept | F18: 0.49842816 | G18: 0.015719077 | H18: 31.708488 | I18: 8.3263326e-204 | J18: 0.46761298 | K18: 0.52924334 | L18: 0.46761298 | M18: 0.52924334 | P18: Intercept | Q18: 0.051495927 | R18: 0.0015837006 | S18: 32.516202 | T18: 2.1415692e-213 | U18: 0.04839129 | V18: 0.054600563 | W18: 0.04839129 | X18: 0.054600563
A19: 2.57 | B19: =Data!D19 -> 0.27 | C19: =Data!E19 -> 0.07 | E19: Load_Time | F19: -0.00058932094 | G19: 0.007610368 | H19: -0.077436589 | I19: 0.93827888 | J19: -0.015508446 | K19: 0.014329804 | L19: -0.015508446 | M19: 0.014329804 | P19: Load_Time | Q19: -0.00071124122 | R19: 0.00076674629 | S19: -0.9276096 | T19: 0.35364827 | U19: -0.0022143464 | V19: 0.00079186398 | W19: -0.0022143464 | X19: 0.00079186398
A20: 2.55 | B20: =Data!D20 -> 0.51 | C20: =Data!E20 -> 0.03
A21: 1.47 | B21: =Data!D21 -> 0.88 | C21: =Data!E21 -> 0.08
A22: 2.47 | B22: =Data!D22 -> 0.04 | C22: =Data!E22 -> 0.01
A23: 1.83 | B23: =Data!D23 -> 0.51 | C23: =Data!E23 -> 0.04
A24: 3.14 | B24: =Data!D24 -> 0.05 | C24: =Data!E24 -> 0.03 | E24: SUMMARY OUTPUT | F24: No significant impact of Bounce Rate on Conversion rate
A25: 2.25 | B25: =Data!D25 -> 0.46 | C25: =Data!E25 -> 0.06
A26: 1.91 | B26: =Data!D26 -> 0.63 | C26: =Data!E26 -> 0.05 | E26: Regression Statistics
A27: 1.61 | B27: =Data!D27 -> 0.74 | C27: =Data!E27 -> 0.05 | E27: Multiple R | F27: 0.0054459868
A28: 2.44 | B28: =Data!D28 -> 0.14 | C28: =Data!E28 -> 0.06 | E28: R Square | F28: 2.9658772e-05
A29: 1.54 | B29: =Data!D29 -> 0.17 | C29: =Data!E29 -> 0.04 | E29: Adjusted R Square | F29: -0.00014078103
A30: 1.01 | B30: =Data!D30 -> 0.47 | C30: =Data!E30 -> 0.02 | E30: Standard Error | F30: 0.029137138
A31: 2.43 | B31: =Data!D31 -> 1 | C31: =Data!E31 -> 0.07 | E31: Observations | F31: 5869
A32: 1.6 | B32: =Data!D32 -> 0.36 | C32: =Data!E32 -> 0.08
A33: 1.83 | B33: =Data!D33 -> 0.43 | C33: =Data!E33 -> 0.05 | E33: ANOVA
A34: 2.42 | B34: =Data!D34 -> 0.43 | C34: =Data!E34 -> 0.06 | F34: df | G34: SS | H34: MS | I34: F | J34: Significance F
A35: 2.36 | B35: =Data!D35 -> 0.08 | C35: =Data!E35 -> 0.05 | E35: Regression | F35: 1 | G35: 0.00014773246 | H35: 0.00014773246 | I35: 0.17401318 | J35: 0.67658479
A36: 2.3 | B36: =Data!D36 -> 0.77 | C36: =Data!E36 -> 0.01 | E36: Residual | F36: 5867 | G36: 4.9809236 | H36: 0.00084897284
A37: 1.54 | B37: =Data!D37 -> 0.25 | C37: =Data!E37 -> 0.04 | E37: Total | F37: 5868 | G37: 4.9810714
A38: 2.03 | B38: =Data!D38 -> 0.7 | C38: =Data!E38 -> 0
A39: 1.72 | B39: =Data!D39 -> 0.48 | C39: =Data!E39 -> 0.07 | F39: Coefficients | G39: Standard Error | H39: t Stat | I39: P-value | J39: Lower 95% | K39: Upper 95% | L39: Lower 95.0% | M39: Upper 95.0%
A40: 2.12 | B40: =Data!D40 -> 0.61 | C40: =Data!E40 -> 0.05 | E40: Intercept | F40: 0.049797007 | G40: 0.00075662568 | H40: 65.814588 | I40: 0 | J40: 0.048313742 | K40: 0.051280272 | L40: 0.048313742 | M40: 0.051280272
...

Sheet Test
A1: Load_Time | B1: =Data!I1 -> Visitor_Type
A2: 2.38 | B2: =Data!I3 -> Returning | D2: New Visitors | E2: Returning Visitors
A3: 2.21 | B3: =Data!I8 -> New | D3: 2.38 | E3: 2.59 | G3: t-Test: Two-Sample Assuming Equal Variances
A4: 1.72 | B4: =Data!I9 -> Returning | D4: 2.21 | E4: 2.65
A5: 2.54 | B5: =Data!I10 -> Returning | D5: 1.72 | E5: 2 | H5: New Visitors | I5: Returning Visitors
A6: 2.22 | B6: =Data!I11 -> New | D6: 2.54 | E6: 2.19 | G6: Mean | H6: 2.0139983 | I6: 1.9916298
A7: 2.21 | B7: =Data!I14 -> Returning | D7: 2.22 | E7: 1.51 | G7: Variance | H7: 0.24727289 | I7: 0.24406014
A8: 2.8 | B8: =Data!I16 -> New | D8: 2.21 | E8: 2.27 | G8: Observations | H8: 3519 | I8: 2350
A9: 2.12 | B9: =Data!I17 -> New | D9: 2.8 | E9: 2.07 | G9: Pooled Variance | H9: 0.24598659
A10: 2.2 | B10: =Data!I18 -> Returning | D10: 2.12 | E10: 1.96 | G10: Hypothesized Mean Difference | H10: 0
A11: 2.55 | B11: =Data!I20 -> New | D11: 2.2 | E11: 2.57 | G11: df | H11: 5867
A12: 1.47 | B12: =Data!I21 -> New | D12: 2.55 | E12: 2.47 | G12: t Stat | H12: 1.6929448
A13: 3.14 | B13: =Data!I24 -> Returning | D13: 1.47 | E13: 1.83 | G13: P(T<=t) one-tail | H13: 0.045259528
A14: 2.25 | B14: =Data!I25 -> New | D14: 3.14 | E14: 1.54 | G14: t Critical one-tail | H14: 1.6451134
A15: 1.91 | B15: =Data!I26 -> New | D15: 2.25 | E15: 1.01 | G15: P(T<=t) two-tail | H15: 0.090519057
A16: 1.61 | B16: =Data!I27 -> Returning | D16: 1.91 | E16: 1.6 | G16: t Critical two-tail | H16: 1.9603684
A17: 2.44 | B17: =Data!I28 -> Returning | D17: 1.61 | E17: 2.36
A18: 2.43 | B18: =Data!I31 -> New | D18: 2.44 | E18: 1.72
A19: 1.83 | B19: =Data!I33 -> Returning | D19: 2.43 | E19: 2.12
A20: 2.42 | B20: =Data!I34 -> Returning | D20: 1.83 | E20: 2.07
A21: 2.3 | B21: =Data!I36 -> Returning | D21: 2.42 | E21: 1.88
A22: 1.54 | B22: =Data!I37 -> Returning | D22: 2.3 | E22: 1.83
A23: 2.03 | B23: =Data!I38 -> New | D23: 1.54 | E23: 3.12
A24: 2.5 | B24: =Data!I42 -> New | D24: 2.03 | E24: 1.79
A25: 1.28 | B25: =Data!I45 -> Returning | D25: 2.5 | E25: 2.13
A26: 2.46 | B26: =Data!I47 -> Returning | D26: 1.28 | E26: 1.8
A27: 1.57 | B27: =Data!I48 -> Returning | D27: 2.46 | E27: 1.38
A28: 2.39 | B28: =Data!I49 -> Returning | D28: 1.57 | E28: 2.61
A29: 1.54 | B29: =Data!I50 -> Returning | D29: 2.39 | E29: 1.1
A30: 1.95 | B30: =Data!I51 -> New | D30: 1.54 | E30: 1.68
A31: 1.96 | B31: =Data!I54 -> New | D31: 1.95 | E31: 2.13
A32: 1.54 | B32: =Data!I55 -> New | D32: 1.96 | E32: 2.08
A33: 1.48 | B33: =Data!I57 -> New | D33: 1.54 | E33: 1.33
A34: 2.67 | B34: =Data!I62 -> Returning | D34: 1.48 | E34: 2.09
A35: 1.49 | B35: =Data!I68 -> Returning | D35: 2.67 | E35: 2.58
A36: 2.36 | B36: =Data!I69 -> New | D36: 1.49 | E36: 2.55
A37: 2.13 | B37: =Data!I70 -> New | D37: 2.36 | E37: 2.16
A38: 2.79 | B38: =Data!I71 -> Returning | D38: 2.13 | E38: 2.22
A39: 1.91 | B39: =Data!I73 -> New | D39: 2.79 | E39: 1.36
A40: 2.13 | B40: =Data!I76 -> New | D40: 1.91 | E40: 1.86
...

Sheet Test2
A1: Visitor_Type | B1: =Data!D1 -> Bounce_Rate
A2: New | B2: =Data!D3 -> 0.1 | D2: New Visitors BR | E2: Returning Visitors BR | G2: t-Test: Two-Sample Assuming Equal Variances
A3: New | B3: =Data!D8 -> 0.24 | D3: 0.51 | E3: 0.8
A4: New | B4: =Data!D9 -> 0.12 | D4: 0.67 | E4: 0.24 | H4: New Visitors BR | I4: Returning Visitors BR
A5: New | B5: =Data!D10 -> 0.21 | D5: 0.26 | E5: 0.82 | G5: Mean | H5: 0.49784314 | I5: 0.49635319
A6: New | B6: =Data!D11 -> 0.1 | D6: 0.16 | E6: 0.9 | G6: Variance | H6: 0.08424239 | I6: 0.082706363
A7: New | B7: =Data!D14 -> 0.4 | D7: 0.36 | E7: 0.03 | G7: Observations | H7: 3519 | I7: 2350
A8: New | B8: =Data!D16 -> 0.55 | D8: 0.18 | E8: 0.71 | G8: Pooled Variance | H8: 0.083627403
A9: New | B9: =Data!D17 -> 0.67 | D9: 0.15 | E9: 0.33 | G9: Hypothesized Mean Difference | H9: 0
A10: New | B10: =Data!D18 -> 0.16 | D10: 0.08 | E10: 0.73 | G10: df | H10: 5867
A11: New | B11: =Data!D20 -> 0.51 | D11: 0.48 | E11: 0.92 | G11: t Stat | H11: 0.19340053
A12: New | B12: =Data!D21 -> 0.88 | D12: 0.44 | E12: 0.27 | G12: P(T<=t) one-tail | H12: 0.423326
A13: New | B13: =Data!D24 -> 0.05 | D13: 0.56 | E13: 0.84 | G13: t Critical one-tail | H13: 1.6451134
A14: New | B14: =Data!D25 -> 0.46 | D14: 0.06 | E14: 0.27 | G14: P(T<=t) two-tail | H14: 0.84665199
A15: New | B15: =Data!D26 -> 0.63 | D15: 0.81 | E15: 0.02 | G15: t Critical two-tail | H15: 1.9603684
A16: New | B16: =Data!D27 -> 0.74 | D16: 0.76 | E16: 0.54
A17: New | B17: =Data!D28 -> 0.14 | D17: 0.28 | E17: 0.59
A18: New | B18: =Data!D31 -> 1 | D18: 0.09 | E18: 0.85
A19: New | B19: =Data!D33 -> 0.43 | D19: 0.04 | E19: 0.87
A20: New | B20: =Data!D34 -> 0.43 | D20: 0.29 | E20: 0.36
A21: New | B21: =Data!D36 -> 0.77 | D21: 0.8 | E21: 0.95
A22: New | B22: =Data!D37 -> 0.25 | D22: 0.62 | E22: 0.67
A23: New | B23: =Data!D38 -> 0.7 | D23: 0.84 | E23: 0.71
A24: New | B24: =Data!D42 -> 0.89 | D24: 0.26 | E24: 0.8
A25: New | B25: =Data!D45 -> 0.8 | D25: 0.5 | E25: 0.78
A26: New | B26: =Data!D47 -> 0.34 | D26: 0.04 | E26: 0.95
A27: New | B27: =Data!D48 -> 0.98 | D27: 1 | E27: 0.9
A28: New | B28: =Data!D49 -> 0.28 | D28: 0.72 | E28: 0.17
A29: New | B29: =Data!D50 -> 0.95 | D29: 0.17 | E29: 0.09
A30: New | B30: =Data!D51 -> 0.16 | D30: 0.3 | E30: 0.77
A31: New | B31: =Data!D54 -> 0 | D31: 0.14 | E31: 0.47
A32: New | B32: =Data!D55 -> 0.26 | D32: 0.61 | E32: 0.63
A33: New | B33: =Data!D57 -> 0.99 | D33: 0.12 | E33: 0.02
A34: New | B34: =Data!D62 -> 0.4 | D34: 0.79 | E34: 0.41
A35: New | B35: =Data!D68 -> 0.23 | D35: 0.08 | E35: 0.04
A36: New | B36: =Data!D69 -> 0.37 | D36: 0.3 | E36: 0.1
A37: New | B37: =Data!D70 -> 0.05 | D37: 0.29 | E37: 0.12
A38: New | B38: =Data!D71 -> 0.59 | D38: 0.43 | E38: 0.47
A39: New | B39: =Data!D73 -> 0.76 | D39: 0.55 | E39: 0.96
A40: New | B40: =Data!D76 -> 0.18 | D40: 0.16 | E40: 0.89
...

Sheet Test3
A1: Visitor_Type | B1: =Data!E1 -> Conversion_Rate
A2: New | B2: =Data!E3 -> 0.05 | D2: New Visitors CR | E2: Returning Visitors CR | G2: t-Test: Two-Sample Assuming Equal Variances
A3: New | B3: =Data!E8 -> 0.01 | D3: 0.07 | E3: 0.04
A4: New | B4: =Data!E9 -> 0.06 | D4: 0.03 | E4: 0.04 | H4: New Visitors CR | I4: Returning Visitors CR
A5: New | B5: =Data!E10 -> 0.07 | D5: 0.02 | E5: 0.05 | G5: Mean | H5: 0.049769821 | I5: 0.050519149
A6: New | B6: =Data!E11 -> 0.08 | D6: 0.01 | E6: 0.09 | G6: Variance | H6: 0.00086018009 | I6: 0.00083191428
A7: New | B7: =Data!E14 -> 0.02 | D7: 0.06 | E7: 0.08 | G7: Observations | H7: 3519 | I7: 2350
A8: New | B8: =Data!E16 -> 0.09 | D8: 0.07 | E8: 0.08 | G8: Pooled Variance | H8: 0.00084886317
A9: New | B9: =Data!E17 -> 0.08 | D9: 0.02 | E9: 0.03 | G9: Hypothesized Mean Difference | H9: 0
A10: New | B10: =Data!E18 -> 0.08 | D10: 0.02 | E10: 0.07 | G10: df | H10: 5867
A11: New | B11: =Data!E20 -> 0.03 | D11: 0.03 | E11: 0.1 | G11: t Stat | H11: -0.96541625
A12: New | B12: =Data!E21 -> 0.08 | D12: 0.02 | E12: 0.09 | G12: P(T<=t) one-tail | H12: 0.16718808
A13: New | B13: =Data!E24 -> 0.03 | D13: 0.02 | E13: 0.05 | G13: t Critical one-tail | H13: 1.6451134
A14: New | B14: =Data!E25 -> 0.06 | D14: 0.02 | E14: 0.06 | G14: P(T<=t) two-tail | H14: 0.33437616
A15: New | B15: =Data!E26 -> 0.05 | D15: 0.09 | E15: 0 | G15: t Critical two-tail | H15: 1.9603684
A16: New | B16: =Data!E27 -> 0.05 | D16: 0.01 | E16: 0.1
A17: New | B17: =Data!E28 -> 0.06 | D17: 0.09 | E17: 0.01
A18: New | B18: =Data!E31 -> 0.07 | D18: 0.07 | E18: 0.01
A19: New | B19: =Data!E33 -> 0.05 | D19: 0.01 | E19: 0.07
A20: New | B20: =Data!E34 -> 0.06 | D20: 0 | E20: 0.02
A21: New | B21: =Data!E36 -> 0.01 | D21: 0.03 | E21: 0.09
A22: New | B22: =Data!E37 -> 0.04 | D22: 0.1 | E22: 0.05
A23: New | B23: =Data!E38 -> 0 | D23: 0.07 | E23: 0.05
A24: New | B24: =Data!E42 -> 0.05 | D24: 0.08 | E24: 0.09
A25: New | B25: =Data!E45 -> 0.1 | D25: 0.08 | E25: 0.04
A26: New | B26: =Data!E47 -> 0.08 | D26: 0.01 | E26: 0.07
A27: New | B27: =Data!E48 -> 0.08 | D27: 0.07 | E27: 0.01
A28: New | B28: =Data!E49 -> 0.04 | D28: 0.07 | E28: 0.09
A29: New | B29: =Data!E50 -> 0.04 | D29: 0.05 | E29: 0.02
A30: New | B30: =Data!E51 -> 0.1 | D30: 0.05 | E30: 0.09
A31: New | B31: =Data!E54 -> 0.02 | D31: 0.07 | E31: 0.02
A32: New | B32: =Data!E55 -> 0.07 | D32: 0.05 | E32: 0.09
A33: New | B33: =Data!E57 -> 0.02 | D33: 0.06 | E33: 0.05
A34: New | B34: =Data!E62 -> 0.02 | D34: 0.04 | E34: 0.06
A35: New | B35: =Data!E68 -> 0.09 | D35: 0.05 | E35: 0.08
A36: New | B36: =Data!E69 -> 0.01 | D36: 0.1 | E36: 0.01
A37: New | B37: =Data!E70 -> 0.01 | D37: 0.08 | E37: 0.06
A38: New | B38: =Data!E71 -> 0.08 | D38: 0.01 | E38: 0.03
A39: New | B39: =Data!E73 -> 0.07 | D39: 0.09 | E39: 0.07
A40: New | B40: =Data!E76 -> 0.06 | D40: 0.07 | E40: 0.07
...

Sheet Test4
A1: Visitor_Type | B1: =Data!C1 -> Session_Duration
A2: New | B2: =Data!C3 -> 221.4 | D2: New Visitors SD | E2: Returning Visitors SD | G2: t-Test: Two-Sample Assuming Equal Variances
A3: New | B3: =Data!C5 -> 695.65 | D3: 128.42 | E3: 110.66
A4: New | B4: =Data!C6 -> 65.83 | D4: 12.56 | E4: 502.83 | H4: New Visitors SD | I4: Returning Visitors SD
A5: New | B5: =Data!C8 -> 43.38 | D5: 61.05 | E5: 79.22 | G5: Mean | H5: 304.18357 | I5: 293.71157
A6: New | B6: =Data!C9 -> 447.47 | D6: 343.13 | E6: 351.78 | G6: Variance | H6: 91262.929 | I6: 87080.586
A7: New | B7: =Data!C11 -> 792.71 | D7: 11.06 | E7: 321.41 | G7: Observations | H7: 3519 | I7: 2350
A8: New | B8: =Data!C14 -> 1359.49 | D8: 52.87 | E8: 257.67 | G8: Pooled Variance | H8: 89588.424
A9: New | B9: =Data!C15 -> 328.43 | D9: 289.62 | E9: 300.1 | G9: Hypothesized Mean Difference | H9: 0
A10: New | B10: =Data!C20 -> 122.37 | D10: 508.51 | E10: 28.14 | G10: df | H10: 5867
A11: New | B11: =Data!C22 -> 466.44 | D11: 76.2 | E11: 90.73 | G11: t Stat | H11: 1.3133044
A12: New | B12: =Data!C23 -> 140.37 | D12: 774.98 | E12: 262.27 | G12: P(T<=t) one-tail | H12: 0.094565882
A13: New | B13: =Data!C25 -> 4.91 | D13: 399.16 | E13: 160.79 | G13: t Critical one-tail | H13: 1.6451134
A14: New | B14: =Data!C27 -> 8.93 | D14: 216.76 | E14: 223.69 | G14: P(T<=t) two-tail | H14: 0.18913176
A15: New | B15: =Data!C30 -> 280.83 | D15: 431.15 | E15: 32.56 | G15: t Critical two-tail | H15: 1.9603684
A16: New | B16: =Data!C32 -> 131.28 | D16: 271.25 | E16: 31.35
A17: New | B17: =Data!C33 -> 17.18 | D17: 197.73 | E17: 76.93
A18: New | B18: =Data!C34 -> 65.04 | D18: 87.24 | E18: 16.92
A19: New | B19: =Data!C35 -> 684.4 | D19: 1000.37 | E19: 84.24
A20: New | B20: =Data!C37 -> 468.48 | D20: 262.21 | E20: 381.02
A21: New | B21: =Data!C38 -> 39.77 | D21: 9.29 | E21: 24.21
A22: New | B22: =Data!C39 -> 43.5 | D22: 280.92 | E22: 14.43
A23: New | B23: =Data!C43 -> 309.13 | D23: 289.72 | E23: 787.91
A24: New | B24: =Data!C44 -> 217.8 | D24: 720.48 | E24: 201.36
A25: New | B25: =Data!C48 -> 13.22 | D25: 68.34 | E25: 442.1
A26: New | B26: =Data!C51 -> 15.44 | D26: 134.61 | E26: 755.82
A27: New | B27: =Data!C55 -> 191.56 | D27: 3.67 | E27: 62.31
A28: New | B28: =Data!C56 -> 5.44 | D28: 68.78 | E28: 19.91
A29: New | B29: =Data!C57 -> 24.65 | D29: 376.71 | E29: 5.13
A30: New | B30: =Data!C58 -> 280.92 | D30: 452.86 | E30: 613.49
A31: New | B31: =Data!C60 -> 355.5 | D31: 740.01 | E31: 428.87
A32: New | B32: =Data!C61 -> 461.68 | D32: 251.57 | E32: 208.71
A33: New | B33: =Data!C63 -> 43.09 | D33: 120.54 | E33: 176.06
A34: New | B34: =Data!C64 -> 182.37 | D34: 394.56 | E34: 650.53
A35: New | B35: =Data!C66 -> 443.63 | D35: 2.11 | E35: 91.7
A36: New | B36: =Data!C67 -> 37.32 | D36: 241.05 | E36: 71.76
A37: New | B37: =Data!C68 -> 209.45 | D37: 324.27 | E37: 57.4
A38: New | B38: =Data!C69 -> 766.78 | D38: 745.2 | E38: 199.14
A39: New | B39: =Data!C70 -> 173.97 | D39: 206.95 | E39: 2166.2
A40: New | B40: =Data!C71 -> 544.97 | D40: 176.27 | E40: 1022.42
...

Sheet Test5
A1: Traffic_Source | B1: =Data!D1 -> Bounce_Rate | C1: =Data!E1 -> Conversion_Rate
A2: Direct | B2: =Data!D4 -> 0.8 | C2: =Data!E4 -> 0.03
A3: Direct | B3: =Data!D7 -> 0.51 | C3: =Data!E7 -> 0.04 | E3: Referral | G3: Social Media | I3: Direct | K3: Organic
A4: Direct | B4: =Data!D8 -> 0.24 | C4: =Data!E8 -> 0.01 | E4: BR | F4: CR | G4: BR | H4: CR | I4: BR | J4: CR | K4: BR | L4: CR | N4: t-Test: Two-Sample Assuming Equal Variances | O4: No significant impact
A5: Direct | B5: =Data!D9 -> 0.12 | C5: =Data!E9 -> 0.06 | E5: 0.52 | F5: 0.09 | G5: 0.56 | H5: 0.08 | I5: 0.49 | J5: 0.1 | K5: 0.95 | L5: 0.02
A6: Direct | B6: =Data!D13 -> 1 | C6: =Data!E13 -> 0.08 | E6: 0.66 | F6: 0.03 | G6: 0.13 | H6: 0.03 | I6: 0.02 | J6: 0.07 | K6: 0.38 | L6: 0 | O6: 0.08 | P6: 0.1
A7: Direct | B7: =Data!D20 -> 0.51 | C7: =Data!E20 -> 0.03 | E7: 0.48 | F7: 0.09 | G7: 0.36 | H7: 0.01 | I7: 0.61 | J7: 0 | K7: 0.78 | L7: 0.01 | N7: Mean | O7: 0.04985469 | P7: 0.050806994
A8: Direct | B8: =Data!D23 -> 0.51 | C8: =Data!E23 -> 0.04 | E8: 0.15 | F8: 0 | G8: 0.08 | H8: 0.04 | I8: 0.28 | J8: 0 | K8: 0.96 | L8: 0.06 | N8: Variance | O8: 0.00085867021 | P8: 0.00085533756
A9: Direct | B9: =Data!D25 -> 0.46 | C9: =Data!E25 -> 0.06 | E9: 0.99 | F9: 0.07 | G9: 0.25 | H9: 0.09 | I9: 0.28 | J9: 0.08 | K9: 0.11 | L9: 0.06 | N9: Observations | O9: 1514 | P9: 1487
A10: Direct | B10: =Data!D27 -> 0.74 | C10: =Data!E27 -> 0.05 | E10: 0.15 | F10: 0.07 | G10: 0.97 | H10: 0.02 | I10: 0.26 | J10: 0.07 | K10: 0.42 | L10: 0.08 | N10: Pooled Variance | O10: 0.00085701889
A11: Direct | B11: =Data!D28 -> 0.14 | C11: =Data!E28 -> 0.06 | E11: 0.71 | F11: 0.02 | G11: 0.98 | H11: 0.05 | I11: 0.65 | J11: 0.05 | K11: 0.28 | L11: 0.03 | N11: Hypothesized Mean Difference | O11: 0
A12: Direct | B12: =Data!D29 -> 0.17 | C12: =Data!E29 -> 0.04 | E12: 0.17 | F12: 0.07 | G12: 0.27 | H12: 0.07 | I12: 0.1 | J12: 0.01 | K12: 0.6 | L12: 0.09 | N12: df | O12: 2999
A13: Direct | B13: =Data!D39 -> 0.48 | C13: =Data!E39 -> 0.07 | E13: 0.36 | F13: 0.1 | G13: 0.11 | H13: 0.05 | I13: 0.81 | J13: 0.04 | K13: 0.38 | L13: 0.05 | N13: t Stat | O13: -0.89097601
A14: Direct | B14: =Data!D50 -> 0.95 | C14: =Data!E50 -> 0.04 | E14: 0.65 | F14: 0.02 | G14: 0.78 | H14: 0.04 | I14: 0.89 | J14: 0.06 | K14: 0.39 | L14: 0.02 | N14: P(T<=t) one-tail | O14: 0.18650676
A15: Direct | B15: =Data!D52 -> 0.39 | C15: =Data!E52 -> 0.04 | E15: 0.87 | F15: 0.08 | G15: 0.85 | H15: 0.04 | I15: 0.93 | J15: 0.01 | K15: 0.76 | L15: 0.08 | N15: t Critical one-tail | O15: 1.6453619
A16: Direct | B16: =Data!D56 -> 0.09 | C16: =Data!E56 -> 0.04 | E16: 0.87 | F16: 0.01 | G16: 0.03 | H16: 0.03 | I16: 0.67 | J16: 0.01 | K16: 0.85 | L16: 0.07 | N16: P(T<=t) two-tail | O16: 0.37301351
A17: Direct | B17: =Data!D57 -> 0.99 | C17: =Data!E57 -> 0.02 | E17: 0.1 | F17: 0.1 | G17: 0.39 | H17: 0.09 | I17: 0.05 | J17: 0.08 | K17: 0.58 | L17: 0.06 | N17: t Critical two-tail | O17: 1.9607553
A18: Direct | B18: =Data!D61 -> 0.67 | C18: =Data!E61 -> 0.02 | E18: 0.92 | F18: 0.09 | G18: 0.59 | H18: 0 | I18: 0.86 | J18: 0.08 | K18: 0.89 | L18: 0.04
A19: Direct | B19: =Data!D69 -> 0.37 | C19: =Data!E69 -> 0.01 | E19: 0.22 | F19: 0.03 | G19: 0.19 | H19: 0.02 | I19: 0.26 | J19: 0.08 | K19: 0.81 | L19: 0.01
A20: Direct | B20: =Data!D70 -> 0.05 | C20: =Data!E70 -> 0.01 | E20: 0.68 | F20: 0.01 | G20: 0.16 | H20: 0.02 | I20: 0.17 | J20: 0.08 | K20: 0.58 | L20: 0.01
A21: Direct | B21: =Data!D73 -> 0.76 | C21: =Data!E73 -> 0.07 | E21: 0.95 | F21: 0.03 | G21: 0.93 | H21: 0.01 | I21: 0.84 | J21: 0 | K21: 0.56 | L21: 0.04
A22: Direct | B22: =Data!D76 -> 0.18 | C22: =Data!E76 -> 0.06 | E22: 0.98 | F22: 0.01 | G22: 0.5 | H22: 0.06 | I22: 0.39 | J22: 0.03 | K22: 0.08 | L22: 0.07
A23: Direct | B23: =Data!D79 -> 0.77 | C23: =Data!E79 -> 0.05 | E23: 0.99 | F23: 0.08 | G23: 0.37 | H23: 0.03 | I23: 0.55 | J23: 0 | K23: 0.24 | L23: 0.06
A24: Direct | B24: =Data!D81 -> 0.97 | C24: =Data!E81 -> 0.08 | E24: 0.27 | F24: 0.01 | G24: 0.86 | H24: 0.05 | I24: 0.97 | J24: 0.04 | K24: 0.43 | L24: 0.07
A25: Direct | B25: =Data!D83 -> 0.29 | C25: =Data!E83 -> 0.06 | E25: 0.72 | F25: 0.02 | G25: 0.5 | H25: 0.08 | I25: 0.33 | J25: 0.07 | K25: 0.96 | L25: 0.07
A26: Direct | B26: =Data!D90 -> 0.39 | C26: =Data!E90 -> 0.04 | E26: 0.51 | F26: 0.02 | G26: 0.62 | H26: 0.01 | I26: 0.91 | J26: 0 | K26: 0.65 | L26: 0.05
A27: Direct | B27: =Data!D96 -> 0.67 | C27: =Data!E96 -> 0.01 | E27: 0.46 | F27: 0.03 | G27: 0.53 | H27: 0.08 | I27: 0.11 | J27: 0.1 | K27: 0.27 | L27: 0.1
A28: Direct | B28: =Data!D97 -> 0.4 | C28: =Data!E97 -> 0.09 | E28: 0.43 | F28: 0.05 | G28: 1 | H28: 0.02 | I28: 1 | J28: 0.04 | K28: 0.82 | L28: 0.06
A29: Direct | B29: =Data!D102 -> 0.34 | C29: =Data!E102 -> 0.03 | E29: 0.05 | F29: 0.01 | G29: 0.42 | H29: 0.02 | I29: 0.39 | J29: 0.06 | K29: 0.64 | L29: 0.07
A30: Direct | B30: =Data!D106 -> 0.14 | C30: =Data!E106 -> 0.01 | E30: 0.32 | F30: 0.04 | G30: 0.33 | H30: 0.08 | I30: 0.37 | J30: 0.03 | K30: 0.84 | L30: 0.03
A31: Direct | B31: =Data!D107 -> 0.13 | C31: =Data!E107 -> 0.07 | E31: 0.75 | F31: 0.05 | G31: 0.27 | H31: 0.02 | I31: 0.19 | J31: 0.02 | K31: 0.52 | L31: 0.05
A32: Direct | B32: =Data!D111 -> 0.37 | C32: =Data!E111 -> 0.05 | E32: 0.78 | F32: 0.06 | G32: 0.39 | H32: 0.01 | I32: 0.85 | J32: 0.06 | K32: 0.53 | L32: 0.04
A33: Direct | B33: =Data!D115 -> 0.58 | C33: =Data!E115 -> 0.04 | E33: 0.57 | F33: 0 | G33: 0.34 | H33: 0.04 | I33: 1 | J33: 0.04 | K33: 0.5 | L33: 0.07
A34: Direct | B34: =Data!D121 -> 0.18 | C34: =Data!E121 -> 0.01 | E34: 0.45 | F34: 0.03 | G34: 0.96 | H34: 0.05 | I34: 0.75 | J34: 0 | K34: 0.66 | L34: 0.03
A35: Direct | B35: =Data!D124 -> 0.43 | C35: =Data!E124 -> 0.08 | E35: 0.03 | F35: 0 | G35: 0.29 | H35: 0.02 | I35: 0.31 | J35: 0.01 | K35: 0.33 | L35: 0.04
A36: Direct | B36: =Data!D129 -> 0.76 | C36: =Data!E129 -> 0.08 | E36: 0.47 | F36: 0.04 | G36: 0.51 | H36: 0.05 | I36: 0.16 | J36: 0.04 | K36: 0.33 | L36: 0.02
A37: Direct | B37: =Data!D132 -> 0.89 | C37: =Data!E132 -> 0.01 | E37: 0.48 | F37: 0.03 | G37: 0.96 | H37: 0.04 | I37: 0.9 | J37: 0.09 | K37: 0.14 | L37: 0.06
A38: Direct | B38: =Data!D138 -> 0.58 | C38: =Data!E138 -> 0.06 | E38: 0.76 | F38: 0.03 | G38: 0.71 | H38: 0.07 | I38: 0.98 | J38: 0.05 | K38: 0.99 | L38: 0.09
A39: Direct | B39: =Data!D139 -> 0.54 | C39: =Data!E139 -> 0.04 | E39: 0.87 | F39: 0.02 | G39: 0.16 | H39: 0.06 | I39: 0.58 | J39: 0.08 | K39: 0.31 | L39: 0.05
A40: Direct | B40: =Data!D141 -> 0.69 | C40: =Data!E141 -> 0.07 | E40: 0.2 | F40: 0.08 | G40: 0.04 | H40: 0.02 | I40: 0.43 | J40: 0.06 | K40: 0.25 | L40: 0.05
...

Sheet Location
A1: Location | B1: =Data!B1 -> Page_Views | C1: Location | D1: =Data!C1 -> Session_Duration | E1: Location | F1: =Data!H1 -> Load_Time | G1: Location | H1: =Data!D1 -> Bounce_Rate | I1: Location | J1: =Data!E1 -> Conversion_Rate | N1: Average
A2: Jacksonville | B2: =Data!B2 -> 5 | C2: Jacksonville | D2: =Data!C2 -> 711.33 | E2: Jacksonville | F2: =Data!H2 -> 1.31 | G2: Jacksonville | H2: =Data!D2 -> 0.57 | I2: Jacksonville | J2: =Data!E2 -> 0.05 | M2: Location | N2: Page views | O2: Session duration | P2: Load time | Q2: Bounce rate | R2: Conversion rate
A3: Columbus | B3: =Data!B3 -> 4 | C3: Columbus | D3: =Data!C3 -> 221.4 | E3: Columbus | F3: =Data!H3 -> 2.01 | G3: Columbus | H3: =Data!D3 -> 0.1 | I3: Columbus | J3: =Data!E3 -> 0.05 | M3: {=_xlfn.UNIQUE(A2:A5870,FALSE)} -> Jacksonville | N3: =AVERAGEIF($A$2:$B$5870,M3,$B$2:$B$5870) -> 5.1800766 | O3: =AVERAGEIF($C$2:$D$5870,M3,$D$2:$D$5870) -> 310.91 | P3: =AVERAGEIF($E$2:$F$5870,M3,$F$2:$F$5870) -> 1.9957471 | Q3: =AVERAGEIF($G$2:$H$5870,M3,$H$2:$H$5870) -> 0.47708812 | R3: =AVERAGEIF($I$2:$J$5870,M3,$J$2:$J$5870) -> 0.050536398
A4: Indianapolis | B4: =Data!B4 -> 4 | C4: Indianapolis | D4: =Data!C4 -> 704.4 | E4: Indianapolis | F4: =Data!H4 -> 2.38 | G4: Indianapolis | H4: =Data!D4 -> 0.8 | I4: Indianapolis | J4: =Data!E4 -> 0.03 | M4: Columbus | N4: =AVERAGEIF($A$2:$B$5870,M4,$B$2:$B$5870) -> 4.9628253 | O4: =AVERAGEIF($C$2:$D$5870,M4,$D$2:$D$5870) -> 283.28082 | P4: =AVERAGEIF($E$2:$F$5870,M4,$F$2:$F$5870) -> 1.9760595 | Q4: =AVERAGEIF($G$2:$H$5870,M4,$H$2:$H$5870) -> 0.49553903 | R4: =AVERAGEIF($I$2:$J$5870,M4,$J$2:$J$5870) -> 0.052527881
A5: Phoenix | B5: =Data!B5 -> 5 | C5: Phoenix | D5: =Data!C5 -> 695.65 | E5: Phoenix | F5: =Data!H5 -> 2.21 | G5: Phoenix | H5: =Data!D5 -> 0.26 | I5: Phoenix | J5: =Data!E5 -> 0.06 | M5: Indianapolis | N5: =AVERAGEIF($A$2:$B$5870,M5,$B$2:$B$5870) -> 4.92 | O5: =AVERAGEIF($C$2:$D$5870,M5,$D$2:$D$5870) -> 284.8944 | P5: =AVERAGEIF($E$2:$F$5870,M5,$F$2:$F$5870) -> 2.0110333 | Q5: =AVERAGEIF($G$2:$H$5870,M5,$H$2:$H$5870) -> 0.4847 | R5: =AVERAGEIF($I$2:$J$5870,M5,$J$2:$J$5870) -> 0.050266667
A6: Columbus | B6: =Data!B6 -> 5 | C6: Columbus | D6: =Data!C6 -> 65.83 | E6: Columbus | F6: =Data!H6 -> 2.22 | G6: Columbus | H6: =Data!D6 -> 0.55 | I6: Columbus | J6: =Data!E6 -> 0.03 | M6: Phoenix | N6: =AVERAGEIF($A$2:$B$5870,M6,$B$2:$B$5870) -> 5.03367 | O6: =AVERAGEIF($C$2:$D$5870,M6,$D$2:$D$5870) -> 313.69788 | P6: =AVERAGEIF($E$2:$F$5870,M6,$F$2:$F$5870) -> 2.0088215 | Q6: =AVERAGEIF($G$2:$H$5870,M6,$H$2:$H$5870) -> 0.49185185 | R6: =AVERAGEIF($I$2:$J$5870,M6,$J$2:$J$5870) -> 0.050740741
A7: Chicago | B7: =Data!B7 -> 3 | C7: Chicago | D7: =Data!C7 -> 143.69 | E7: Chicago | F7: =Data!H7 -> 1.93 | G7: Chicago | H7: =Data!D7 -> 0.51 | I7: Chicago | J7: =Data!E7 -> 0.04 | M7: Chicago | N7: =AVERAGEIF($A$2:$B$5870,M7,$B$2:$B$5870) -> 5.0427046 | O7: =AVERAGEIF($C$2:$D$5870,M7,$D$2:$D$5870) -> 277.79544 | P7: =AVERAGEIF($E$2:$F$5870,M7,$F$2:$F$5870) -> 1.9986477 | Q7: =AVERAGEIF($G$2:$H$5870,M7,$H$2:$H$5870) -> 0.50697509 | R7: =AVERAGEIF($I$2:$J$5870,M7,$J$2:$J$5870) -> 0.047330961
A8: Phoenix | B8: =Data!B8 -> 5 | C8: Phoenix | D8: =Data!C8 -> 43.38 | E8: Phoenix | F8: =Data!H8 -> 1.21 | G8: Phoenix | H8: =Data!D8 -> 0.24 | I8: Phoenix | J8: =Data!E8 -> 0.01 | M8: Dallas | N8: =AVERAGEIF($A$2:$B$5870,M8,$B$2:$B$5870) -> 5.1103896 | O8: =AVERAGEIF($C$2:$D$5870,M8,$D$2:$D$5870) -> 309.01159 | P8: =AVERAGEIF($E$2:$F$5870,M8,$F$2:$F$5870) -> 2.0480519 | Q8: =AVERAGEIF($G$2:$H$5870,M8,$H$2:$H$5870) -> 0.47746753 | R8: =AVERAGEIF($I$2:$J$5870,M8,$J$2:$J$5870) -> 0.048571429
A9: Dallas | B9: =Data!B9 -> 4 | C9: Dallas | D9: =Data!C9 -> 447.47 | E9: Dallas | F9: =Data!H9 -> 1.08 | G9: Dallas | H9: =Data!D9 -> 0.12 | I9: Dallas | J9: =Data!E9 -> 0.06 | M9: Seattle | N9: =AVERAGEIF($A$2:$B$5870,M9,$B$2:$B$5870) -> 5.2315789 | O9: =AVERAGEIF($C$2:$D$5870,M9,$D$2:$D$5870) -> 297.3013 | P9: =AVERAGEIF($E$2:$F$5870,M9,$F$2:$F$5870) -> 2.0007368 | Q9: =AVERAGEIF($G$2:$H$5870,M9,$H$2:$H$5870) -> 0.52101754 | R9: =AVERAGEIF($I$2:$J$5870,M9,$J$2:$J$5870) -> 0.048561404
A10: Jacksonville | B10: =Data!B10 -> 6 | C10: Jacksonville | D10: =Data!C10 -> 210.43 | E10: Jacksonville | F10: =Data!H10 -> 2.14 | G10: Jacksonville | H10: =Data!D10 -> 0.21 | I10: Jacksonville | J10: =Data!E10 -> 0.07 | M10: New York | N10: =AVERAGEIF($A$2:$B$5870,M10,$B$2:$B$5870) -> 5.0690789 | O10: =AVERAGEIF($C$2:$D$5870,M10,$D$2:$D$5870) -> 278.54878 | P10: =AVERAGEIF($E$2:$F$5870,M10,$F$2:$F$5870) -> 1.9680263 | Q10: =AVERAGEIF($G$2:$H$5870,M10,$H$2:$H$5870) -> 0.49944079 | R10: =AVERAGEIF($I$2:$J$5870,M10,$J$2:$J$5870) -> 0.048881579
A11: Phoenix | B11: =Data!B11 -> 7 | C11: Phoenix | D11: =Data!C11 -> 792.71 | E11: Phoenix | F11: =Data!H11 -> 2.1 | G11: Phoenix | H11: =Data!D11 -> 0.1 | I11: Phoenix | J11: =Data!E11 -> 0.08 | M11: Austin | N11: =AVERAGEIF($A$2:$B$5870,M11,$B$2:$B$5870) -> 5.1935484 | O11: =AVERAGEIF($C$2:$D$5870,M11,$D$2:$D$5870) -> 291.92884 | P11: =AVERAGEIF($E$2:$F$5870,M11,$F$2:$F$5870) -> 2.0514516 | Q11: =AVERAGEIF($G$2:$H$5870,M11,$H$2:$H$5870) -> 0.475 | R11: =AVERAGEIF($I$2:$J$5870,M11,$J$2:$J$5870) -> 0.048548387
A12: Indianapolis | B12: =Data!B12 -> 2 | C12: Indianapolis | D12: =Data!C12 -> 70.04 | E12: Indianapolis | F12: =Data!H12 -> 2.49 | G12: Indianapolis | H12: =Data!D12 -> 0.28 | I12: Indianapolis | J12: =Data!E12 -> 0.09 | M12: Fort Worth | N12: =AVERAGEIF($A$2:$B$5870,M12,$B$2:$B$5870) -> 4.8006873 | O12: =AVERAGEIF($C$2:$D$5870,M12,$D$2:$D$5870) -> 321.23701 | P12: =AVERAGEIF($E$2:$F$5870,M12,$F$2:$F$5870) -> 1.9816495 | Q12: =AVERAGEIF($G$2:$H$5870,M12,$H$2:$H$5870) -> 0.50931271 | R12: =AVERAGEIF($I$2:$J$5870,M12,$J$2:$J$5870) -> 0.0504811
A13: Seattle | B13: =Data!B13 -> 5 | C13: Seattle | D13: =Data!C13 -> 349.78 | E13: Seattle | F13: =Data!H13 -> 1.3 | G13: Seattle | H13: =Data!D13 -> 1 | I13: Seattle | J13: =Data!E13 -> 0.08 | M13: Washington | N13: =AVERAGEIF($A$2:$B$5870,M13,$B$2:$B$5870) -> 4.9427609 | O13: =AVERAGEIF($C$2:$D$5870,M13,$D$2:$D$5870) -> 324.18761 | P13: =AVERAGEIF($E$2:$F$5870,M13,$F$2:$F$5870) -> 1.9916835 | Q13: =AVERAGEIF($G$2:$H$5870,M13,$H$2:$H$5870) -> 0.51851852 | R13: =AVERAGEIF($I$2:$J$5870,M13,$J$2:$J$5870) -> 0.047003367
A14: New York | B14: =Data!B14 -> 5 | C14: New York | D14: =Data!C14 -> 1359.49 | E14: New York | F14: =Data!H14 -> 1.36 | G14: New York | H14: =Data!D14 -> 0.4 | I14: New York | J14: =Data!E14 -> 0.02 | M14: Denver | N14: =AVERAGEIF($A$2:$B$5870,M14,$B$2:$B$5870) -> 5.1543624 | O14: =AVERAGEIF($C$2:$D$5870,M14,$D$2:$D$5870) -> 282.16886 | P14: =AVERAGEIF($E$2:$F$5870,M14,$F$2:$F$5870) -> 2.0383893 | Q14: =AVERAGEIF($G$2:$H$5870,M14,$H$2:$H$5870) -> 0.47083893 | R14: =AVERAGEIF($I$2:$J$5870,M14,$J$2:$J$5870) -> 0.048993289
A15: Chicago | B15: =Data!B15 -> 6 | C15: Chicago | D15: =Data!C15 -> 328.43 | E15: Chicago | F15: =Data!H15 -> 2.1 | G15: Chicago | H15: =Data!D15 -> 0.86 | I15: Chicago | J15: =Data!E15 -> 0.02 | M15: Charlotte | N15: =AVERAGEIF($A$2:$B$5870,M15,$B$2:$B$5870) -> 5.0221519 | O15: =AVERAGEIF($C$2:$D$5870,M15,$D$2:$D$5870) -> 300.03367 | P15: =AVERAGEIF($E$2:$F$5870,M15,$F$2:$F$5870) -> 2 | Q15: =AVERAGEIF($G$2:$H$5870,M15,$H$2:$H$5870) -> 0.49987342 | R15: =AVERAGEIF($I$2:$J$5870,M15,$J$2:$J$5870) -> 0.051265823
... A22: Austin | B22: =Data!B22 -> 11 | C22: Austin | D22: =Data!C22 -> 466.44 | E22: Austin | F22: =Data!H22 -> 2.43 | G22: Austin | H22: =Data!D22 -> 0.04 | I22: Austin | J22: =Data!E22 -> 0.01 | M22: San Francisco | N22: =AVERAGEIF($A$2:$B$5870,M22,$B$2:$B$5870) -> 4.9633333 | O22: =AVERAGEIF($C$2:$D$5870,M22,$D$2:$D$5870) -> 311.31877 | P22: =AVERAGEIF($E$2:$F$5870,M22,$F$2:$F$5870) -> 1.9913667 | Q22: =AVERAGEIF($G$2:$H$5870,M22,$H$2:$H$5870) -> 0.47913333 | R22: =AVERAGEIF($I$2:$J$5870,M22,$J$2:$J$5870) -> 0.0492
A23: Washington | B23: =Data!B23 -> 4 | C23: Washington | D23: =Data!C23 -> 140.37 | E23: Washington | F23: =Data!H23 -> 1.37 | G23: Washington | H23: =Data!D23 -> 0.51 | I23: Washington | J23: =Data!E23 -> 0.04
A24: Denver | B24: =Data!B24 -> 3 | C24: Denver | D24: =Data!C24 -> 396.11 | E24: Denver | F24: =Data!H24 -> 2.14 | G24: Denver | H24: =Data!D24 -> 0.05 | I24: Denver | J24: =Data!E24 -> 0.03 | M24: Row Labels | N24: Count of Visitor_Type
A25: Charlotte | B25: =Data!B25 -> 8 | C25: Charlotte | D25: =Data!C25 -> 4.91 | E25: Charlotte | F25: =Data!H25 -> 1.51 | G25: Charlotte | H25: =Data!D25 -> 0.46 | I25: Charlotte | J25: =Data!E25 -> 0.06 | M25: Austin | N25: 310
A26: Philadelphia | B26: =Data!B26 -> 3 | C26: Philadelphia | D26: =Data!C26 -> 4.48 | E26: Philadelphia | F26: =Data!H26 -> 2.47 | G26: Philadelphia | H26: =Data!D26 -> 0.63 | I26: Philadelphia | J26: =Data!E26 -> 0.05 | M26: New | N26: 188
A27: Houston | B27: =Data!B27 -> 3 | C27: Houston | D27: =Data!C27 -> 8.93 | E27: Houston | F27: =Data!H27 -> 1.27 | G27: Houston | H27: =Data!D27 -> 0.74 | I27: Houston | J27: =Data!E27 -> 0.05 | M27: Returning | N27: 122
A28: Washington | B28: =Data!B28 -> 5 | C28: Washington | D28: =Data!C28 -> 74.29 | E28: Washington | F28: =Data!H28 -> 1.77 | G28: Washington | H28: =Data!D28 -> 0.14 | I28: Washington | J28: =Data!E28 -> 0.06 | M28: Charlotte | N28: 316
A29: Washington | B29: =Data!B29 -> 8 | C29: Washington | D29: =Data!C29 -> 140.52 | E29: Washington | F29: =Data!H29 -> 2.64 | G29: Washington | H29: =Data!D29 -> 0.17 | I29: Washington | J29: =Data!E29 -> 0.04 | M29: New | N29: 206
A30: New York | B30: =Data!B30 -> 3 | C30: New York | D30: =Data!C30 -> 280.83 | E30: New York | F30: =Data!H30 -> 1.39 | G30: New York | H30: =Data!D30 -> 0.47 | I30: New York | J30: =Data!E30 -> 0.02 | M30: Returning | N30: 110
A31: Seattle | B31: =Data!B31 -> 2 | C31: Seattle | D31: =Data!C31 -> 1278.77 | E31: Seattle | F31: =Data!H31 -> 1.39 | G31: Seattle | H31: =Data!D31 -> 1 | I31: Seattle | J31: =Data!E31 -> 0.07 | M31: Chicago | N31: 281
A32: Chicago | B32: =Data!B32 -> 5 | C32: Chicago | D32: =Data!C32 -> 131.28 | E32: Chicago | F32: =Data!H32 -> 2.6 | G32: Chicago | H32: =Data!D32 -> 0.36 | I32: Chicago | J32: =Data!E32 -> 0.08 | M32: New | N32: 183
A33: San Jose | B33: =Data!B33 -> 3 | C33: San Jose | D33: =Data!C33 -> 17.18 | E33: San Jose | F33: =Data!H33 -> 1.7 | G33: San Jose | H33: =Data!D33 -> 0.43 | I33: San Jose | J33: =Data!E33 -> 0.05 | M33: Returning | N33: 98
A34: Columbus | B34: =Data!B34 -> 8 | C34: Columbus | D34: =Data!C34 -> 65.04 | E34: Columbus | F34: =Data!H34 -> 2.85 | G34: Columbus | H34: =Data!D34 -> 0.43 | I34: Columbus | J34: =Data!E34 -> 0.06 | M34: Columbus | N34: 269
A35: Columbus | B35: =Data!B35 -> 10 | C35: Columbus | D35: =Data!C35 -> 684.4 | E35: Columbus | F35: =Data!H35 -> 1.72 | G35: Columbus | H35: =Data!D35 -> 0.08 | I35: Columbus | J35: =Data!E35 -> 0.05 | M35: New | N35: 167
A36: Dallas | B36: =Data!B36 -> 3 | C36: Dallas | D36: =Data!C36 -> 360.57 | E36: Dallas | F36: =Data!H36 -> 2.12 | G36: Dallas | H36: =Data!D36 -> 0.77 | I36: Dallas | J36: =Data!E36 -> 0.01 | M36: Returning | N36: 102
... A85: Phoenix | B85: =Data!B85 -> 9 | C85: Phoenix | D85: =Data!C85 -> 196.81 | E85: Phoenix | F85: =Data!H85 -> 1.3 | G85: Phoenix | H85: =Data!D85 -> 0.45 | I85: Phoenix | J85: =Data!E85 -> 0.05 | M85: Grand Total | N85: 5869
A86: Seattle | B86: =Data!B86 -> 6 | C86: Seattle | D86: =Data!C86 -> 1664.35 | E86: Seattle | F86: =Data!H86 -> 2.24 | G86: Seattle | H86: =Data!D86 -> 0.99 | I86: Seattle | J86: =Data!E86 -> 0.07
A87: Austin | B87: =Data!B87 -> 6 | C87: Austin | D87: =Data!C87 -> 145.32 | E87: Austin | F87: =Data!H87 -> 1.23 | G87: Austin | H87: =Data!D87 -> 0.41 | I87: Austin | J87: =Data!E87 -> 0.01
A88: San Francisco | B88: =Data!B88 -> 9 | C88: San Francisco | D88: =Data!C88 -> 577.5 | E88: San Francisco | F88: =Data!H88 -> 1.74 | G88: San Francisco | H88: =Data!D88 -> 0.2 | I88: San Francisco | J88: =Data!E88 -> 0.03
A89: San Antonio | B89: =Data!B89 -> 4 | C89: San Antonio | D89: =Data!C89 -> 594.9 | E89: San Antonio | F89: =Data!H89 -> 2.06 | G89: San Antonio | H89: =Data!D89 -> 0.94 | I89: San Antonio | J89: =Data!E89 -> 0.08
A90: Fort Worth | B90: =Data!B90 -> 9 | C90: Fort Worth | D90: =Data!C90 -> 79.45 | E90: Fort Worth | F90: =Data!H90 -> 1.77 | G90: Fort Worth | H90: =Data!D90 -> 0.39 | I90: Fort Worth | J90: =Data!E90 -> 0.04
A91: San Antonio | B91: =Data!B91 -> 2 | C91: San Antonio | D91: =Data!C91 -> 29.89 | E91: San Antonio | F91: =Data!H91 -> 3.06 | G91: San Antonio | H91: =Data!D91 -> 0.69 | I91: San Antonio | J91: =Data!E91 -> 0.06
A92: San Francisco | B92: =Data!B92 -> 10 | C92: San Francisco | D92: =Data!C92 -> 1114.2 | E92: San Francisco | F92: =Data!H92 -> 2.48 | G92: San Francisco | H92: =Data!D92 -> 0.79 | I92: San Francisco | J92: =Data!E92 -> 0.01
A93: Charlotte | B93: =Data!B93 -> 6 | C93: Charlotte | D93: =Data!C93 -> 166.48 | E93: Charlotte | F93: =Data!H93 -> 2.06 | G93: Charlotte | H93: =Data!D93 -> 0.84 | I93: Charlotte | J93: =Data!E93 -> 0.08
A94: San Diego | B94: =Data!B94 -> 9 | C94: San Diego | D94: =Data!C94 -> 0.67 | E94: San Diego | F94: =Data!H94 -> 1.81 | G94: San Diego | H94: =Data!D94 -> 0.82 | I94: San Diego | J94: =Data!E94 -> 0.01
...
